{"uuid": "6e967b53-cd45-4f03-9fa7-005d0b1c0f2d", "children": ["24c043fd-7037-474c-808a-e5896edec5d1"], "befores": [{"name": "setup_teardown", "status": "broken", "statusDetails": {"message": "Exception: 登录过程失败: 打开登录页面失败: 'function' object has no attribute 'get'\n", "trace": "  File \"D:\\Python39\\lib\\site-packages\\pluggy\\_callers.py\", line 167, in _multicall\n    teardown.throw(outcome._exception)\n  File \"D:\\Python39\\lib\\site-packages\\_pytest\\setuponly.py\", line 36, in pytest_fixture_setup\n    return (yield)\n  File \"D:\\Python39\\lib\\site-packages\\pluggy\\_callers.py\", line 103, in _multicall\n    res = hook_impl.function(*args)\n  File \"D:\\Python39\\lib\\site-packages\\_pytest\\fixtures.py\", line 1140, in pytest_fixture_setup\n    result = call_fixture_func(fixturefunc, request, kwargs)\n  File \"D:\\Python39\\lib\\site-packages\\_pytest\\fixtures.py\", line 891, in call_fixture_func\n    fixture_result = next(generator)\n  File \"E:\\AutoTest\\FgAIHelp\\tests\\base_test.py\", line 30, in setup_teardown\n    login_page.login(\"wxdfg\", \"wxd341134@\")\n  File \"E:\\AutoTest\\FgAIHelp\\pages\\login_page.py\", line 177, in login\n    self.handle_error(f\"登录过程失败: {str(e)}\")\n  File \"E:\\AutoTest\\FgAIHelp\\pages\\login_page.py\", line 54, in handle_error\n    raise Exception(error_msg)\n"}, "start": 1744361420335, "stop": 1744361420335}], "start": 1744361420335, "stop": 1744361420419}